Workbook

Sheet Item Inventory
A1: Bhagavan Medicals Inventory
A2: Item ID | B2: Item Name | C2: Category | D2: Quantity | E2: Supplier | F2: Cost Price | G2: Selling Price | H2: Expiry Date | I2: Number of Days to expire | J2: ABC_Class | K2: FSN_Class
A3: I001 | B3: 4U-Q10 Plus Cap | C3: Vitamins/Minerals | D3: 66 | E3: RSM Pharma | F3: 373.21818 | G3: 410.54 | H3: =_xlfn.XLOOKUP(B3,'[1]Raw Data Sales'!$B:$B,'[1]Raw Data Sales'!$G:$G,0) -> 46388 | I3: =H3-TODAY() -> 319 | J3: =_xlfn.XLOOKUP('Item Inventory'!C3,Table1[Category],Table1[ABC_Class],0) -> A | K3: =_xlfn.XLOOKUP(C3,Table1[Category],Table1[FSN_Class],0) -> F
A4: I002 | B4: AB Next Gel | C4: Pain Relief | D4: 95 | E4: RSM Pharma | F4: 332.22727 | G4: 365.45 | H4: =_xlfn.XLOOKUP(B4,'[1]Raw Data Sales'!$B:$B,'[1]Raw Data Sales'!$G:$G,0) -> 46419 | I4: =H4-TODAY() -> 350 | J4: =_xlfn.XLOOKUP('Item Inventory'!C4,Table1[Category],Table1[ABC_Class],0) -> A | K4: =_xlfn.XLOOKUP(C4,Table1[Category],Table1[FSN_Class],0) -> F
A5: I003 | B5: Accu Chek | C5: Respiratory | D5: 37 | E5: RSM Pharma | F5: 807.16364 | G5: 887.88 | H5: 46113 | I5: =H5-TODAY() -> 44 | J5: =_xlfn.XLOOKUP('Item Inventory'!C5,Table1[Category],Table1[ABC_Class],0) -> C | K5: =_xlfn.XLOOKUP(C5,Table1[Category],Table1[FSN_Class],0) -> S
A6: I004 | B6: Acne UV Gel | C6: Sunscreen | D6: 100 | E6: RSM Pharma | F6: 600.92727 | G6: 661.02 | H6: =_xlfn.XLOOKUP(B6,'[1]Raw Data Sales'!$B:$B,'[1]Raw Data Sales'!$G:$G,0) -> 46388 | I6: =H6-TODAY() -> 319 | J6: =_xlfn.XLOOKUP('Item Inventory'!C6,Table1[Category],Table1[ABC_Class],0) -> B | K6: =_xlfn.XLOOKUP(C6,Table1[Category],Table1[FSN_Class],0) -> N
A7: I005 | B7: Acnewin Face Wash | C7: Skincare | D7: 66 | E7: Mahaveer Medi Sales | F7: 155.87273 | G7: 171.46 | H7: =_xlfn.XLOOKUP(B7,'[1]Raw Data Sales'!$B:$B,'[1]Raw Data Sales'!$G:$G,0) -> 46905 | I7: =H7-TODAY() -> 836 | J7: =_xlfn.XLOOKUP('Item Inventory'!C7,Table1[Category],Table1[ABC_Class],0) -> A | K7: =_xlfn.XLOOKUP(C7,Table1[Category],Table1[FSN_Class],0) -> F
A8: I213 | B8: Xaliderm Solution | C8: Immunosuppresant | D8: 87 | E8: - | F8: - | G8: 299 | H8: 45901 | I8: =H8-TODAY() -> -168 | J8: C | K8: N
A9: I007 | B9: Alerid Syrup | C9: Anti-microbial | D9: 33 | E9: RSM Pharma | F9: 29.227273 | G9: 32.15 | H9: =_xlfn.XLOOKUP(B9,'[1]Raw Data Sales'!$B:$B,'[1]Raw Data Sales'!$G:$G,0) -> 46874 | I9: =H9-TODAY() -> 805 | J9: =_xlfn.XLOOKUP('Item Inventory'!C9,Table1[Category],Table1[ABC_Class],0) -> A | K9: =_xlfn.XLOOKUP(C9,Table1[Category],Table1[FSN_Class],0) -> F
A10: I008 | B10: Allegra 180MG Tab | C10: Anti-microbial | D10: 88 | E10: RSM Pharma | F10: 196.5 | G10: 216.15 | H10: =_xlfn.XLOOKUP(B10,'[1]Raw Data Sales'!$B:$B,'[1]Raw Data Sales'!$G:$G,0) -> 46508 | I10: =H10-TODAY() -> 439 | J10: =_xlfn.XLOOKUP('Item Inventory'!C10,Table1[Category],Table1[ABC_Class],0) -> A | K10: =_xlfn.XLOOKUP(C10,Table1[Category],Table1[FSN_Class],0) -> F
A11: I194 | B11: Terbinaforce 500 | C11: Anti-microbial | D11: 50 | E11: - | F11: - | G11: 184.47 | H11: 45839 | I11: =H11-TODAY() -> -230 | J11: =_xlfn.XLOOKUP('Item Inventory'!C196,Table1[Category],Table1[ABC_Class],0) -> A | K11: =_xlfn.XLOOKUP(C11,Table1[Category],Table1[FSN_Class],0) -> F
A12: I010 | B12: Amorolkite Cream | C12: Anti-microbial | D12: 94 | E12: Pride Pharma | F12: 374 | G12: 411.4 | H12: 46357 | I12: =H12-TODAY() -> 288 | J12: =_xlfn.XLOOKUP('Item Inventory'!C12,Table1[Category],Table1[ABC_Class],0) -> A | K12: =_xlfn.XLOOKUP(C12,Table1[Category],Table1[FSN_Class],0) -> F
A13: I011 | B13: Aquahance Mois Soap | C13: Skincare | D13: 56 | E13: Tulsi Corporation | F13: 169.49091 | G13: 186.44 | H13: 45748 | I13: =H13-TODAY() -> -321 | J13: =_xlfn.XLOOKUP('Item Inventory'!C13,Table1[Category],Table1[ABC_Class],0) -> A | K13: =_xlfn.XLOOKUP(C13,Table1[Category],Table1[FSN_Class],0) -> F
A14: I012 | B14: Aquahance Moisture | C14: Skincare | D14: 25 | E14: Ram Agencies | F14: 169.49091 | G14: 186.44 | H14: 46054 | I14: =H14-TODAY() -> -15 | J14: =_xlfn.XLOOKUP('Item Inventory'!C14,Table1[Category],Table1[ABC_Class],0) -> A | K14: =_xlfn.XLOOKUP(C14,Table1[Category],Table1[FSN_Class],0) -> F
A15: I013 | B15: Ascoril SF Syrup | C15: Cold/Cough | D15: 99 | E15: Ram Agencies | F15: 109.41818 | G15: 120.36 | H15: =_xlfn.XLOOKUP(B15,'[1]Raw Data Sales'!$B:$B,'[1]Raw Data Sales'!$G:$G,0) -> 46508 | I15: =H15-TODAY() -> 439 | J15: =_xlfn.XLOOKUP('Item Inventory'!C15,Table1[Category],Table1[ABC_Class],0) -> C | K15: =_xlfn.XLOOKUP(C15,Table1[Category],Table1[FSN_Class],0) -> N
A16: I014 | B16: Asthalin 4MG Tabs | C16: Respiratory | D16: 84 | E16: Ram Agencies | F16: 198.79091 | G16: 218.67 | H16: =_xlfn.XLOOKUP(B16,'[1]Raw Data Sales'!$B:$B,'[1]Raw Data Sales'!$G:$G,0) -> 46478 | I16: =H16-TODAY() -> 409 | J16: =_xlfn.XLOOKUP('Item Inventory'!C16,Table1[Category],Table1[ABC_Class],0) -> C | K16: =_xlfn.XLOOKUP(C16,Table1[Category],Table1[FSN_Class],0) -> S
A17: I015 | B17: Aten 50MG Tab | C17: Cardiovascular | D17: 83 | E17: Ram Agencies | F17: 24.381818 | G17: 26.82 | H17: =_xlfn.XLOOKUP(B17,'[1]Raw Data Sales'!$B:$B,'[1]Raw Data Sales'!$G:$G,0) -> 46874 | I17: =H17-TODAY() -> 805 | J17: =_xlfn.XLOOKUP('Item Inventory'!C17,Table1[Category],Table1[ABC_Class],0) -> B | K17: =_xlfn.XLOOKUP(C17,Table1[Category],Table1[FSN_Class],0) -> F
A18: I016 | B18: Atogla Lotion | C18: Skincare | D18: 41 | E18: Ram Agencies | F18: 391.37273 | G18: 430.51 | H18: 46137 | I18: =H18-TODAY() -> 68 | J18: =_xlfn.XLOOKUP('Item Inventory'!C18,Table1[Category],Table1[ABC_Class],0) -> A | K18: =_xlfn.XLOOKUP(C18,Table1[Category],Table1[FSN_Class],0) -> F
A19: I017 | B19: Atogla Skin Lotion | C19: Skincare | D19: 84 | E19: Tulsi Corporation | F19: 391.37273 | G19: 430.51 | H19: =_xlfn.XLOOKUP(B19,'[1]Raw Data Sales'!$B:$B,'[1]Raw Data Sales'!$G:$G,0) -> 46478 | I19: =H19-TODAY() -> 409 | J19: =_xlfn.XLOOKUP('Item Inventory'!C19,Table1[Category],Table1[ABC_Class],0) -> A | K19: =_xlfn.XLOOKUP(C19,Table1[Category],Table1[FSN_Class],0) -> F
A20: I018 | B20: Atorva Gold 10MG Cap | C20: Cardiovascular | D20: 86 | E20: Ram Agencies | F20: 45.172727 | G20: 49.69 | H20: =_xlfn.XLOOKUP(B20,'[1]Raw Data Sales'!$B:$B,'[1]Raw Data Sales'!$G:$G,0) -> 46478 | I20: =H20-TODAY() -> 409 | J20: =_xlfn.XLOOKUP('Item Inventory'!C20,Table1[Category],Table1[ABC_Class],0) -> B | K20: =_xlfn.XLOOKUP(C20,Table1[Category],Table1[FSN_Class],0) -> F
A21: I193 | B21: Tenolol 50MG | C21: Cardiovascular | D21: 37 | E21: - | F21: - | G21: 35 | H21: 46357 | I21: =H21-TODAY() -> 288 | J21: B | K21: =_xlfn.XLOOKUP(C21,Table1[Category],Table1[FSN_Class],0) -> F
A22: I020 | B22: Azee 500 Tabs | C22: Anti-microbial | D22: 81 | E22: Mahaveer Medi Sales | F22: 87.190909 | G22: 95.91 | H22: 46357 | I22: =H22-TODAY() -> 288 | J22: =_xlfn.XLOOKUP('Item Inventory'!C22,Table1[Category],Table1[ABC_Class],0) -> A | K22: =_xlfn.XLOOKUP(C22,Table1[Category],Table1[FSN_Class],0) -> F
A23: I021 | B23: Aziderm Plus Cream | C23: Skincare | D23: 53 | E23: Ram Agencies | F23: 225.97273 | G23: 248.57 | H23: 45748 | I23: =H23-TODAY() -> -321 | J23: =_xlfn.XLOOKUP('Item Inventory'!C23,Table1[Category],Table1[ABC_Class],0) -> A | K23: =_xlfn.XLOOKUP(C23,Table1[Category],Table1[FSN_Class],0) -> F
A24: I022 | B24: Azithral 500mg Tab | C24: Anti-microbial | D24: 80 | E24: Ram Agencies | F24: 87.190909 | G24: 95.91 | H24: 46091 | I24: =H24-TODAY() -> 22 | J24: =_xlfn.XLOOKUP('Item Inventory'!C24,Table1[Category],Table1[ABC_Class],0) -> A | K24: =_xlfn.XLOOKUP(C24,Table1[Category],Table1[FSN_Class],0) -> F
A25: I023 | B25: Bandy Plus Tab | C25: Anti-microbial | D25: 98 | E25: Ram Agencies | F25: 21.981818 | G25: 24.18 | H25: =_xlfn.XLOOKUP(B25,'[1]Raw Data Sales'!$B:$B,'[1]Raw Data Sales'!$G:$G,0) -> 46753 | I25: =H25-TODAY() -> 684 | J25: =_xlfn.XLOOKUP('Item Inventory'!C25,Table1[Category],Table1[ABC_Class],0) -> A | K25: =_xlfn.XLOOKUP(C25,Table1[Category],Table1[FSN_Class],0) -> F
A26: I024 | B26: Becadexamin Caps | C26: Vitamins/Minerals | D26: 82 | E26: Ram Agencies | F26: 84 | G26: 92.4 | H26: =_xlfn.XLOOKUP(B26,'[1]Raw Data Sales'!$B:$B,'[1]Raw Data Sales'!$G:$G,0) -> 46296 | I26: =H26-TODAY() -> 227 | J26: =_xlfn.XLOOKUP('Item Inventory'!C26,Table1[Category],Table1[ABC_Class],0) -> A | K26: =_xlfn.XLOOKUP(C26,Table1[Category],Table1[FSN_Class],0) -> F
A27: I025 | B27: Becosules Plus Syrup | C27: Vitamins/Minerals | D27: 54 | E27: Ram Agencies | F27: 71.418182 | G27: 78.56 | H27: =_xlfn.XLOOKUP(B27,'[1]Raw Data Sales'!$B:$B,'[1]Raw Data Sales'!$G:$G,0) -> 46204 | I27: =H27-TODAY() -> 135 | J27: =_xlfn.XLOOKUP('Item Inventory'!C27,Table1[Category],Table1[ABC_Class],0) -> A | K27: =_xlfn.XLOOKUP(C27,Table1[Category],Table1[FSN_Class],0) -> F
A28: I026 | B28: Behance Sunscreen | C28: Sunscreen | D28: 95 | E28: Avenues Pharma | F28: 555.3 | G28: 610.83 | H28: 46127 | I28: =H28-TODAY() -> 58 | J28: =_xlfn.XLOOKUP('Item Inventory'!C28,Table1[Category],Table1[ABC_Class],0) -> B | K28: =_xlfn.XLOOKUP(C28,Table1[Category],Table1[FSN_Class],0) -> N
A29: I027 | B29: Betadine G 2% | C29: First Aid | D29: 71 | E29: Ram Agencies | F29: 131.81818 | G29: 145 | H29: =_xlfn.XLOOKUP(B29,'[1]Raw Data Sales'!$B:$B,'[1]Raw Data Sales'!$G:$G,0) -> 46447 | I29: =H29-TODAY() -> 378 | J29: =_xlfn.XLOOKUP('Item Inventory'!C29,Table1[Category],Table1[ABC_Class],0) -> C | K29: =_xlfn.XLOOKUP(C29,Table1[Category],Table1[FSN_Class],0) -> N
A30: I028 | B30: Bilatis 20MG Tabs | C30: Anti-microbial | D30: 96 | E30: Ram Agencies | F30: 85.718182 | G30: 94.29 | H30: =_xlfn.XLOOKUP(B30,'[1]Raw Data Sales'!$B:$B,'[1]Raw Data Sales'!$G:$G,0) -> 46447 | I30: =H30-TODAY() -> 378 | J30: =_xlfn.XLOOKUP('Item Inventory'!C30,Table1[Category],Table1[ABC_Class],0) -> A | K30: =_xlfn.XLOOKUP(C30,Table1[Category],Table1[FSN_Class],0) -> F
A31: I029 | B31: Bimat LS Eye Drops | C31: Body Care | D31: 96 | E31: Ram Agencies | F31: 188.30909 | G31: 207.14 | H31: =_xlfn.XLOOKUP(B31,'[1]Raw Data Sales'!$B:$B,'[1]Raw Data Sales'!$G:$G,0) -> 46478 | I31: =H31-TODAY() -> 409 | J31: =_xlfn.XLOOKUP('Item Inventory'!C31,Table1[Category],Table1[ABC_Class],0) -> A | K31: =_xlfn.XLOOKUP(C31,Table1[Category],Table1[FSN_Class],0) -> S
A32: I030 | B32: Brufen 600 Tab | C32: Pain Relief | D32: 24 | E32: RSM Pharma | F32: 27.518182 | G32: 30.27 | H32: =_xlfn.XLOOKUP(B32,'[1]Raw Data Sales'!$B:$B,'[1]Raw Data Sales'!$G:$G,0) -> 46874 | I32: =H32-TODAY() -> 805 | J32: =_xlfn.XLOOKUP('Item Inventory'!C32,Table1[Category],Table1[ABC_Class],0) -> A | K32: =_xlfn.XLOOKUP(C32,Table1[Category],Table1[FSN_Class],0) -> F
A33: I031 | B33: Budamate 200 Transcaps | C33: Respiratory | D33: 32 | E33: RSM Pharma | F33: 126.91818 | G33: 139.61 | H33: =_xlfn.XLOOKUP(B33,'[1]Raw Data Sales'!$B:$B,'[1]Raw Data Sales'!$G:$G,0) -> 46508 | I33: =H33-TODAY() -> 439 | J33: =_xlfn.XLOOKUP('Item Inventory'!C33,Table1[Category],Table1[ABC_Class],0) -> C | K33: =_xlfn.XLOOKUP(C33,Table1[Category],Table1[FSN_Class],0) -> S
A34: I032 | B34: BuscoGast Tab | C34: Gastro Tabs | D34: 48 | E34: Mahaveer Medi Sales | F34: 30.272727 | G34: 33.3 | H34: 46151 | I34: =H34-TODAY() -> 82 | J34: =_xlfn.XLOOKUP('Item Inventory'!C34,Table1[Category],Table1[ABC_Class],0) -> B | K34: =_xlfn.XLOOKUP(C34,Table1[Category],Table1[FSN_Class],0) -> S
A35: I033 | B35: BX Shampoo | C35: Body Care | D35: 83 | E35: Ram Agencies | F35: 350.36364 | G35: 385.4 | H35: =_xlfn.XLOOKUP(B35,'[1]Raw Data Sales'!$B:$B,'[1]Raw Data Sales'!$G:$G,0) -> 46539 | I35: =H35-TODAY() -> 470 | J35: =_xlfn.XLOOKUP('Item Inventory'!C35,Table1[Category],Table1[ABC_Class],0) -> A | K35: =_xlfn.XLOOKUP(C35,Table1[Category],Table1[FSN_Class],0) -> S
A36: I034 | B36: Calosoft AF Lotion | C36: Skincare | D36: 49 | E36: Mahaveer Medi Sales | F36: 80.745455 | G36: 88.82 | H36: =_xlfn.XLOOKUP(B36,'[1]Raw Data Sales'!$B:$B,'[1]Raw Data Sales'!$G:$G,0) -> 46478 | I36: =H36-TODAY() -> 409 | J36: =_xlfn.XLOOKUP('Item Inventory'!C36,Table1[Category],Table1[ABC_Class],0) -> A | K36: =_xlfn.XLOOKUP(C36,Table1[Category],Table1[FSN_Class],0) -> F
A37: I035 | B37: Calpsor C Oint | C37: Anti-microbial | D37: 84 | E37: RSM Pharma | F37: 462.85455 | G37: 509.14 | H37: =_xlfn.XLOOKUP(B37,'[1]Raw Data Sales'!$B:$B,'[1]Raw Data Sales'!$G:$G,0) -> 46539 | I37: =H37-TODAY() -> 470 | J37: =_xlfn.XLOOKUP('Item Inventory'!C37,Table1[Category],Table1[ABC_Class],0) -> A | K37: =_xlfn.XLOOKUP(C37,Table1[Category],Table1[FSN_Class],0) -> F
A38: I036 | B38: Candid Cream | C38: Anti-microbial | D38: 56 | E38: Ram Agencies | F38: 65.454545 | G38: 72 | H38: =_xlfn.XLOOKUP(B38,'[1]Raw Data Sales'!$B:$B,'[1]Raw Data Sales'!$G:$G,0) -> 46388 | I38: =H38-TODAY() -> 319 | J38: =_xlfn.XLOOKUP('Item Inventory'!C38,Table1[Category],Table1[ABC_Class],0) -> A | K38: =_xlfn.XLOOKUP(C38,Table1[Category],Table1[FSN_Class],0) -> F
A39: I037 | B39: Candid Cream | C39: Anti-microbial | D39: 59 | E39: RSM Pharma | F39: 65.454545 | G39: 72 | H39: 46143 | I39: =H39-TODAY() -> 74 | J39: =_xlfn.XLOOKUP('Item Inventory'!C39,Table1[Category],Table1[ABC_Class],0) -> A | K39: =_xlfn.XLOOKUP(C39,Table1[Category],Table1[FSN_Class],0) -> F
A40: I038 | B40: Candiforce 200 Caps | C40: Anti-microbial | D40: 42 | E40: Ram Agencies | F40: 163.63636 | G40: 180 | H40: =_xlfn.XLOOKUP(B40,'[1]Raw Data Sales'!$B:$B,'[1]Raw Data Sales'!$G:$G,0) -> 46508 | I40: =H40-TODAY() -> 439 | J40: =_xlfn.XLOOKUP('Item Inventory'!C40,Table1[Category],Table1[ABC_Class],0) -> A | K40: =_xlfn.XLOOKUP(C40,Table1[Category],Table1[FSN_Class],0) -> F
...

Sheet Inventory Control
A1: Category | B1: ABC_Class | C1: FSN_Class | D1: Expiry Risk | E1: Stock Policy | F1: Action Recommended
A2: Skincare | B2: A | C2: =_xlfn.XLOOKUP(A2,'[1]Analysis I'!$G$25:$G$39,'[1]Analysis I'!$L$25:$L$39,0) -> F | D2: HIGH | E2: Small and Frequent Orders | F2: Small batches ordered often to reduce expiry risk.
A3: Anti-microbial | B3: A | C3: =_xlfn.XLOOKUP(A3,'[1]Analysis I'!$G$25:$G$39,'[1]Analysis I'!$L$25:$L$39,0) -> F | D3: LOW | E3: Bulk Order | F3: Large quantity procurement for stable, low-expiry items.
A4: Body Care | B4: A | C4: =_xlfn.XLOOKUP(A4,'[1]Analysis I'!$G$25:$G$39,'[1]Analysis I'!$L$25:$L$39,0) -> S | D4: LOW | E4: Bulk Order | F4: Large quantity procurement for stable, low-expiry items.
A5: Vitamins/Minerals | B5: A | C5: =_xlfn.XLOOKUP(A5,'[1]Analysis I'!$G$25:$G$39,'[1]Analysis I'!$L$25:$L$39,0) -> F | D5: LOW | E5: Bulk Order | F5: Large quantity procurement for stable, low-expiry items.
A6: Pain Relief | B6: A | C6: =_xlfn.XLOOKUP(A6,'[1]Analysis I'!$G$25:$G$39,'[1]Analysis I'!$L$25:$L$39,0) -> F | D6: HIGH | E6: Small and Frequent Orders | F6: Small batches ordered often to reduce expiry risk.
A7: Cardiovascular | B7: B | C7: =_xlfn.XLOOKUP(A7,'[1]Analysis I'!$G$25:$G$39,'[1]Analysis I'!$L$25:$L$39,0) -> F | D7: MODERATE | E7: Controlled Replenishment | F7: Moderate ordering with regular stock review.
A8: Sunscreen | B8: B | C8: =_xlfn.XLOOKUP(A8,'[1]Analysis I'!$G$25:$G$39,'[1]Analysis I'!$L$25:$L$39,0) -> N | D8: MODERATE | E8: Controlled Replenishment | F8: Moderate ordering with regular stock review.
A9: Diabetes | B9: B | C9: =_xlfn.XLOOKUP(A9,'[1]Analysis I'!$G$25:$G$39,'[1]Analysis I'!$L$25:$L$39,0) -> S | D9: MODERATE | E9: Controlled Replenishment | F9: Moderate ordering with regular stock review.
A10: Gastro Tabs | B10: B | C10: =_xlfn.XLOOKUP(A10,'[1]Analysis I'!$G$25:$G$39,'[1]Analysis I'!$L$25:$L$39,0) -> S | D10: LOW | E10: Controlled Replenishment | F10: Moderate ordering with regular stock review.
A11: Respiratory | B11: C | C11: =_xlfn.XLOOKUP(A11,'[1]Analysis I'!$G$25:$G$39,'[1]Analysis I'!$L$25:$L$39,0) -> S | D11: LOW | E11: Order on Demand | F11: Procure only when demand arises.
A12: Cold/Cough | B12: C | C12: =_xlfn.XLOOKUP(A12,'[1]Analysis I'!$G$25:$G$39,'[1]Analysis I'!$L$25:$L$39,0) -> N | D12: LOW | E12: Order on Demand | F12: Procure only when demand arises.
A13: First Aid | B13: C | C13: =_xlfn.XLOOKUP(A13,'[1]Analysis I'!$G$25:$G$39,'[1]Analysis I'!$L$25:$L$39,0) -> N | D13: LOW | E13: Order on Demand | F13: Procure only when demand arises.
... A15: Immunosuppressant | B15: C | C15: =_xlfn.XLOOKUP(A15,'[1]Analysis I'!$G$25:$G$39,'[1]Analysis I'!$L$25:$L$39,0) -> N | D15: HIGH | E15: Discontinued | F15: Stop regular stocking due to persistent losses.
